Workbook

Sheet 1 Setup steps
A1: Just Now - BookingKoala setup pack
A2: Source: owner-approved price table (2 Oct 2026, amended 8-9 Oct) as loaded in the WhatsApp assistant. Prepared 23 Oct 2026; area list extended and approved by the owner 23 Oct 2026. Yellow cells are for you to fill.
A4: # | B4: Step | C4: What to do
A5: 1 | B5: Create account | C5: bookingkoala.com -> Start free trial. Use justnow.cs@gmail.com. Industry: Home cleaning. Currency: AED. Time zone: Asia/Dubai. Language: English (add Arabic later if the plan supports it).
A6: 2 | B6: Company profile | C6: Name: Just Now For Building Cleaning Services. Phone: +971 50 767 7282. Email: Customer.care@justnow.life. Website: https://www.justnow.life. No street address shown to customers.
A7: 3 | B7: Locations (= your zones) | C7: Settings -> Locations. Create 5 locations named exactly: Zone A, Zone B, Zone C, Zone D, Zone E. These are not shown to customers; they only carry the prices. See sheet '3 Zones & Areas' for which area belongs to which zone.
A8: 4 | B8: Service areas | C8: If BookingKoala asks for zip/postal codes, use the area NAME as the code (e.g. 'Al Majaz'). Load every row of sheet '3 Zones & Areas' under its zone. The customer types or picks the area and the zone price applies.
A9: 5 | B9: Service categories | C9: Create 2 bookable services: 'Kitchen deep cleaning' and 'Full house deep cleaning'. Do NOT create sofa/mattress/carpet or commercial as bookable (they are quoted from photos on WhatsApp).
A10: 6 | B10: Pricing variables | C10: For Full house: a 'Home size' dropdown with Studio, 1 BHK, 2 BHK, 3 BHK, Villa 4 BR, Villa 5+ BR. For Kitchen: no size question (always the kitchen row). Then a 'Package' dropdown per size with the 3 options from sheet '2 Packages'. Price = per location (zone). Enter every price from sheet '2 Packages'; never leave a formula or 'from' price.
A11: 7 | B11: Duration | C11: Set each package's duration to its hours (3, 4, 5, 6 or 7 h) and the number of providers to the cleaners count, so the calendar blocks the right time and team.
A12: 8 | B12: Minimum | C12: Zone D must not offer any 3-hour package. Use the location rule to hide the 3-hour option for Zone D (its first package is 2 x 4 h).
A13: 9 | B13: Hours and slots | C13: Settings -> Business hours: every day 08:00-21:00. Arrival windows: 8-12, 12-4, 4-9. Same-day booking allowed until 18:00; after that the earliest slot is tomorrow 8-12. See sheet '4 Hours & Slots'.
A14: 10 | B14: Customer form fields | C14: Name, mobile (+971), email (optional), emirate, area, building/villa + apartment number, notes ('What should the team focus on?'). All mandatory except email. No account creation required to book.
A15: 11 | B15: Payment | C15: Pay on completion (cash, card payment link, bank transfer). In BookingKoala set 'Pay later / no card required' for now. No deposit. No discount codes. No tips. Turn OFF any 'frequency discount' option: regular cleaning is not offered.
... A19: 15 | B19: Go live | C19: Put the BookingKoala link on https://www.justnow.life/book-now (keep ?utm_source=whatsapp on the WhatsApp link) and update the WhatsApp assistant's booking link. Keep the old Webador form until the new one has taken 10 real bookings without a problem.

Sheet 2 Packages
A1: Approved packages (AED, everything included, no VAT shown)
A2: Every row is one price BookingKoala must store. 'Order' 1 = the package shown first / minimum. Do not round, do not show 'from'.
A4: Service | B4: Home size (variable) | C4: Zone (location) | D4: Zone note | E4: Order | F4: Package label | G4: Cleaners (providers) | H4: Hours (duration) | I4: Price AED | J4: Minimum? | L4: Key (helper)
A5: Kitchen deep cleaning | B5: (no size question) | C5: Zone A | D5: Sharjah/Ajman standard | E5: 1 | F5: 2 cleaners x 3 hours | G5: 2 | H5: 3 | I5: 249 | J5: Yes | L5: =IF(B5="(no size question)","Kitchen only / partial / refresh",B5)&"|"&C5&"|"&E5 -> Kitchen only / partial / refresh|Zone A|1
A6: Kitchen deep cleaning | B6: (no size question) | C6: Zone A | D6: Sharjah/Ajman standard | E6: 2 | F6: 2 cleaners x 4 hours | G6: 2 | H6: 4 | I6: 329 | L6: =IF(B6="(no size question)","Kitchen only / partial / refresh",B6)&"|"&C6&"|"&E6 -> Kitchen only / partial / refresh|Zone A|2
A7: Kitchen deep cleaning | B7: (no size question) | C7: Zone A | D7: Sharjah/Ajman standard | E7: 3 | F7: 2 cleaners x 5 hours | G7: 2 | H7: 5 | I7: 419 | L7: =IF(B7="(no size question)","Kitchen only / partial / refresh",B7)&"|"&C7&"|"&E7 -> Kitchen only / partial / refresh|Zone A|3
A8: Kitchen deep cleaning | B8: (no size question) | C8: Zone B | D8: Old Dubai, Silicon Oasis side, UAQ | E8: 1 | F8: 2 cleaners x 3 hours | G8: 2 | H8: 3 | I8: 279 | J8: Yes | L8: =IF(B8="(no size question)","Kitchen only / partial / refresh",B8)&"|"&C8&"|"&E8 -> Kitchen only / partial / refresh|Zone B|1
A9: Kitchen deep cleaning | B9: (no size question) | C9: Zone B | D9: Old Dubai, Silicon Oasis side, UAQ | E9: 2 | F9: 2 cleaners x 4 hours | G9: 2 | H9: 4 | I9: 369 | L9: =IF(B9="(no size question)","Kitchen only / partial / refresh",B9)&"|"&C9&"|"&E9 -> Kitchen only / partial / refresh|Zone B|2
A10: Kitchen deep cleaning | B10: (no size question) | C10: Zone B | D10: Old Dubai, Silicon Oasis side, UAQ | E10: 3 | F10: 2 cleaners x 5 hours | G10: 2 | H10: 5 | I10: 459 | L10: =IF(B10="(no size question)","Kitchen only / partial / refresh",B10)&"|"&C10&"|"&E10 -> Kitchen only / partial / refresh|Zone B|3
A11: Kitchen deep cleaning | B11: (no size question) | C11: Zone E | D11: Far from base (Dubai default price) | E11: 1 | F11: 2 cleaners x 3 hours | G11: 2 | H11: 3 | I11: 309 | J11: Yes | L11: =IF(B11="(no size question)","Kitchen only / partial / refresh",B11)&"|"&C11&"|"&E11 -> Kitchen only / partial / refresh|Zone E|1
A12: Kitchen deep cleaning | B12: (no size question) | C12: Zone E | D12: Far from base (Dubai default price) | E12: 2 | F12: 2 cleaners x 4 hours | G12: 2 | H12: 4 | I12: 409 | L12: =IF(B12="(no size question)","Kitchen only / partial / refresh",B12)&"|"&C12&"|"&E12 -> Kitchen only / partial / refresh|Zone E|2
A13: Kitchen deep cleaning | B13: (no size question) | C13: Zone E | D13: Far from base (Dubai default price) | E13: 3 | F13: 2 cleaners x 5 hours | G13: 2 | H13: 5 | I13: 509 | L13: =IF(B13="(no size question)","Kitchen only / partial / refresh",B13)&"|"&C13&"|"&E13 -> Kitchen only / partial / refresh|Zone E|3
A14: Kitchen deep cleaning | B14: (no size question) | C14: Zone C | D14: New Dubai | E14: 1 | F14: 2 cleaners x 3 hours | G14: 2 | H14: 3 | I14: 329 | J14: Yes | L14: =IF(B14="(no size question)","Kitchen only / partial / refresh",B14)&"|"&C14&"|"&E14 -> Kitchen only / partial / refresh|Zone C|1
A15: Kitchen deep cleaning | B15: (no size question) | C15: Zone C | D15: New Dubai | E15: 2 | F15: 2 cleaners x 4 hours | G15: 2 | H15: 4 | I15: 439 | L15: =IF(B15="(no size question)","Kitchen only / partial / refresh",B15)&"|"&C15&"|"&E15 -> Kitchen only / partial / refresh|Zone C|2
A16: Kitchen deep cleaning | B16: (no size question) | C16: Zone C | D16: New Dubai | E16: 3 | F16: 2 cleaners x 5 hours | G16: 2 | H16: 5 | I16: 549 | L16: =IF(B16="(no size question)","Kitchen only / partial / refresh",B16)&"|"&C16&"|"&E16 -> Kitchen only / partial / refresh|Zone C|3
A17: Kitchen deep cleaning | B17: (no size question) | C17: Zone D | D17: Far areas: 4-hour minimum | E17: 1 | F17: 2 cleaners x 4 hours | G17: 2 | H17: 4 | I17: 439 | J17: Yes | L17: =IF(B17="(no size question)","Kitchen only / partial / refresh",B17)&"|"&C17&"|"&E17 -> Kitchen only / partial / refresh|Zone D|1
A18: Kitchen deep cleaning | B18: (no size question) | C18: Zone D | D18: Far areas: 4-hour minimum | E18: 2 | F18: 2 cleaners x 5 hours | G18: 2 | H18: 5 | I18: 549 | L18: =IF(B18="(no size question)","Kitchen only / partial / refresh",B18)&"|"&C18&"|"&E18 -> Kitchen only / partial / refresh|Zone D|2
A19: Kitchen deep cleaning | B19: (no size question) | C19: Zone D | D19: Far areas: 4-hour minimum | E19: 3 | F19: 2 cleaners x 6 hours | G19: 2 | H19: 6 | I19: 659 | L19: =IF(B19="(no size question)","Kitchen only / partial / refresh",B19)&"|"&C19&"|"&E19 -> Kitchen only / partial / refresh|Zone D|3
A20: Full house deep cleaning | B20: Studio | C20: Zone A | D20: Sharjah/Ajman standard | E20: 1 | F20: 2 cleaners x 3 hours | G20: 2 | H20: 3 | I20: 249 | J20: Yes | L20: =IF(B20="(no size question)","Kitchen only / partial / refresh",B20)&"|"&C20&"|"&E20 -> Studio|Zone A|1
A21: Full house deep cleaning | B21: Studio | C21: Zone A | D21: Sharjah/Ajman standard | E21: 2 | F21: 2 cleaners x 4 hours | G21: 2 | H21: 4 | I21: 329 | L21: =IF(B21="(no size question)","Kitchen only / partial / refresh",B21)&"|"&C21&"|"&E21 -> Studio|Zone A|2
A22: Full house deep cleaning | B22: Studio | C22: Zone A | D22: Sharjah/Ajman standard | E22: 3 | F22: 2 cleaners x 5 hours | G22: 2 | H22: 5 | I22: 419 | L22: =IF(B22="(no size question)","Kitchen only / partial / refresh",B22)&"|"&C22&"|"&E22 -> Studio|Zone A|3
A23: Full house deep cleaning | B23: Studio | C23: Zone B | D23: Old Dubai, Silicon Oasis side, UAQ | E23: 1 | F23: 2 cleaners x 3 hours | G23: 2 | H23: 3 | I23: 279 | J23: Yes | L23: =IF(B23="(no size question)","Kitchen only / partial / refresh",B23)&"|"&C23&"|"&E23 -> Studio|Zone B|1
A24: Full house deep cleaning | B24: Studio | C24: Zone B | D24: Old Dubai, Silicon Oasis side, UAQ | E24: 2 | F24: 2 cleaners x 4 hours | G24: 2 | H24: 4 | I24: 369 | L24: =IF(B24="(no size question)","Kitchen only / partial / refresh",B24)&"|"&C24&"|"&E24 -> Studio|Zone B|2
A25: Full house deep cleaning | B25: Studio | C25: Zone B | D25: Old Dubai, Silicon Oasis side, UAQ | E25: 3 | F25: 2 cleaners x 5 hours | G25: 2 | H25: 5 | I25: 459 | L25: =IF(B25="(no size question)","Kitchen only / partial / refresh",B25)&"|"&C25&"|"&E25 -> Studio|Zone B|3
A26: Full house deep cleaning | B26: Studio | C26: Zone E | D26: Far from base (Dubai default price) | E26: 1 | F26: 2 cleaners x 3 hours | G26: 2 | H26: 3 | I26: 309 | J26: Yes | L26: =IF(B26="(no size question)","Kitchen only / partial / refresh",B26)&"|"&C26&"|"&E26 -> Studio|Zone E|1
A27: Full house deep cleaning | B27: Studio | C27: Zone E | D27: Far from base (Dubai default price) | E27: 2 | F27: 2 cleaners x 4 hours | G27: 2 | H27: 4 | I27: 409 | L27: =IF(B27="(no size question)","Kitchen only / partial / refresh",B27)&"|"&C27&"|"&E27 -> Studio|Zone E|2
A28: Full house deep cleaning | B28: Studio | C28: Zone E | D28: Far from base (Dubai default price) | E28: 3 | F28: 2 cleaners x 5 hours | G28: 2 | H28: 5 | I28: 509 | L28: =IF(B28="(no size question)","Kitchen only / partial / refresh",B28)&"|"&C28&"|"&E28 -> Studio|Zone E|3
A29: Full house deep cleaning | B29: Studio | C29: Zone C | D29: New Dubai | E29: 1 | F29: 2 cleaners x 3 hours | G29: 2 | H29: 3 | I29: 329 | J29: Yes | L29: =IF(B29="(no size question)","Kitchen only / partial / refresh",B29)&"|"&C29&"|"&E29 -> Studio|Zone C|1
A30: Full house deep cleaning | B30: Studio | C30: Zone C | D30: New Dubai | E30: 2 | F30: 2 cleaners x 4 hours | G30: 2 | H30: 4 | I30: 439 | L30: =IF(B30="(no size question)","Kitchen only / partial / refresh",B30)&"|"&C30&"|"&E30 -> Studio|Zone C|2
A31: Full house deep cleaning | B31: Studio | C31: Zone C | D31: New Dubai | E31: 3 | F31: 2 cleaners x 5 hours | G31: 2 | H31: 5 | I31: 549 | L31: =IF(B31="(no size question)","Kitchen only / partial / refresh",B31)&"|"&C31&"|"&E31 -> Studio|Zone C|3
A32: Full house deep cleaning | B32: Studio | C32: Zone D | D32: Far areas: 4-hour minimum | E32: 1 | F32: 2 cleaners x 4 hours | G32: 2 | H32: 4 | I32: 439 | J32: Yes | L32: =IF(B32="(no size question)","Kitchen only / partial / refresh",B32)&"|"&C32&"|"&E32 -> Studio|Zone D|1
A33: Full house deep cleaning | B33: Studio | C33: Zone D | D33: Far areas: 4-hour minimum | E33: 2 | F33: 2 cleaners x 5 hours | G33: 2 | H33: 5 | I33: 549 | L33: =IF(B33="(no size question)","Kitchen only / partial / refresh",B33)&"|"&C33&"|"&E33 -> Studio|Zone D|2
A34: Full house deep cleaning | B34: Studio | C34: Zone D | D34: Far areas: 4-hour minimum | E34: 3 | F34: 2 cleaners x 6 hours | G34: 2 | H34: 6 | I34: 659 | L34: =IF(B34="(no size question)","Kitchen only / partial / refresh",B34)&"|"&C34&"|"&E34 -> Studio|Zone D|3
A35: Full house deep cleaning | B35: 1 BHK | C35: Zone A | D35: Sharjah/Ajman standard | E35: 1 | F35: 3 cleaners x 3 hours | G35: 3 | H35: 3 | I35: 379 | J35: Yes | L35: =IF(B35="(no size question)","Kitchen only / partial / refresh",B35)&"|"&C35&"|"&E35 -> 1 BHK|Zone A|1
A36: Full house deep cleaning | B36: 1 BHK | C36: Zone A | D36: Sharjah/Ajman standard | E36: 2 | F36: 3 cleaners x 4 hours | G36: 3 | H36: 4 | I36: 499 | L36: =IF(B36="(no size question)","Kitchen only / partial / refresh",B36)&"|"&C36&"|"&E36 -> 1 BHK|Zone A|2
A37: Full house deep cleaning | B37: 1 BHK | C37: Zone A | D37: Sharjah/Ajman standard | E37: 3 | F37: 3 cleaners x 5 hours | G37: 3 | H37: 5 | I37: 629 | L37: =IF(B37="(no size question)","Kitchen only / partial / refresh",B37)&"|"&C37&"|"&E37 -> 1 BHK|Zone A|3
A38: Full house deep cleaning | B38: 1 BHK | C38: Zone B | D38: Old Dubai, Silicon Oasis side, UAQ | E38: 1 | F38: 3 cleaners x 3 hours | G38: 3 | H38: 3 | I38: 409 | J38: Yes | L38: =IF(B38="(no size question)","Kitchen only / partial / refresh",B38)&"|"&C38&"|"&E38 -> 1 BHK|Zone B|1
A39: Full house deep cleaning | B39: 1 BHK | C39: Zone B | D39: Old Dubai, Silicon Oasis side, UAQ | E39: 2 | F39: 3 cleaners x 4 hours | G39: 3 | H39: 4 | I39: 549 | L39: =IF(B39="(no size question)","Kitchen only / partial / refresh",B39)&"|"&C39&"|"&E39 -> 1 BHK|Zone B|2
A40: Full house deep cleaning | B40: 1 BHK | C40: Zone B | D40: Old Dubai, Silicon Oasis side, UAQ | E40: 3 | F40: 3 cleaners x 5 hours | G40: 3 | H40: 5 | I40: 689 | L40: =IF(B40="(no size question)","Kitchen only / partial / refresh",B40)&"|"&C40&"|"&E40 -> 1 BHK|Zone B|3
A41: Full house deep cleaning | B41: 1 BHK | C41: Zone E | D41: Far from base (Dubai default price) | E41: 1 | F41: 3 cleaners x 3 hours | G41: 3 | H41: 3 | I41: 459 | J41: Yes | L41: =IF(B41="(no size question)","Kitchen only / partial / refresh",B41)&"|"&C41&"|"&E41 -> 1 BHK|Zone E|1
...

Sheet 3 Zones & Areas
A1: Areas and their zone (load each as a service area under its Zone location)
A2: Dubai and Sharjah: only listed areas have a price. An unlisted Dubai/Sharjah area = 'price on request' (do not book online; send to WhatsApp). Ajman, UAQ, RAK, Fujairah: the emirate's default zone applies to any unlisted area.
A4: Emirate | B4: Emirate (Arabic) | C4: Area (English, as the customer should see it) | D4: Area (Arabic) | E4: Also known as / sub-areas | F4: Zone | G4: Note
A5: Dubai | B5: دبي | C5: Al Nahda | D5: النهدة | E5: Al Nahda 1-2 | F5: Zone B
A6: Dubai | B6: دبي | C6: Al Qusais | D6: القصيص | E6: Al Qusais 1-5 | F6: Zone B
A7: Dubai | B7: دبي | C7: Al Qusais Industrial | F7: Zone B
A8: Dubai | B8: دبي | C8: Deira | D8: ديرة | F8: Zone B
A9: Dubai | B9: دبي | C9: Al Rigga | D9: الرقة | F9: Zone B
A10: Dubai | B10: دبي | C10: Al Muraqqabat | D10: المرقبات | F10: Zone B
A11: Dubai | B11: دبي | C11: Naif | D11: نايف | F11: Zone B
A12: Dubai | B12: دبي | C12: Al Murar | D12: المرر | F12: Zone B
A13: Dubai | B13: دبي | C13: Muteena | D13: المطينة | F13: Zone B
A14: Dubai | B14: دبي | C14: Ayal Nasir | F14: Zone B
A15: Dubai | B15: دبي | C15: Al Buteen | F15: Zone B
A16: Dubai | B16: دبي | C16: Port Saeed | F16: Zone B
A17: Dubai | B17: دبي | C17: Hor Al Anz | D17: هور العنز | F17: Zone B
A18: Dubai | B18: دبي | C18: Abu Hail | D18: أبو هيل | F18: Zone B
A19: Dubai | B19: دبي | C19: Al Baraha | F19: Zone B
A20: Dubai | B20: دبي | C20: Al Wuheida | F20: Zone B
A21: Dubai | B21: دبي | C21: Al Mamzar | D21: الممزر | F21: Zone B
A22: Dubai | B22: دبي | C22: Bur Dubai | D22: بر دبي | F22: Zone B
A23: Dubai | B23: دبي | C23: Al Mankhool | D23: المنخول | F23: Zone B
A24: Dubai | B24: دبي | C24: Al Hamriya | F24: Zone B
A25: Dubai | B25: دبي | C25: Al Karama | D25: الكرامة | F25: Zone B
A26: Dubai | B26: دبي | C26: Oud Metha | D26: عود ميثاء | F26: Zone B
A27: Dubai | B27: دبي | C27: Al Jafiliya | F27: Zone B
A28: Dubai | B28: دبي | C28: Zabeel | D28: زعبيل | F28: Zone B
A29: Dubai | B29: دبي | C29: Al Kifaf | F29: Zone B
A30: Dubai | B30: دبي | C30: Dubai Healthcare City | F30: Zone B
A31: Dubai | B31: دبي | C31: Garhoud | D31: القرهود | E31: Al Garhoud | F31: Zone B
A32: Dubai | B32: دبي | C32: Umm Ramool | F32: Zone B
A33: Dubai | B33: دبي | C33: Al Rashidiya | D33: الراشدية | E33: Al Rashidiya 1-3 | F33: Zone B
A34: Dubai | B34: دبي | C34: Nad Al Hamar | D34: ند الحمر | F34: Zone B
A35: Dubai | B35: دبي | C35: Ras Al Khor | D35: رأس الخور | F35: Zone B
A36: Dubai | B36: دبي | C36: Al Aweer | F36: Zone B
A37: Dubai | B37: دبي | C37: Mirdif | F37: Zone B
A38: Dubai | B38: دبي | C38: Al Mizhar | F38: Zone B
A39: Dubai | B39: دبي | C39: Al Khawaneej | F39: Zone B
A40: Dubai | B40: دبي | C40: Al Twar | F40: Zone B
A41: Dubai | B41: دبي | C41: Muhaisnah | D41: محيصنة | E41: Muhaisnah 1-4 | F41: Zone B
...

Sheet 4 Hours & Slots
A1: Working hours, arrival windows and booking rules
A3: Setting | B3: Value
A4: Working days | B4: Every day, including Friday and public holidays
A5: Working hours | B5: 08:00 - 21:00 (Asia/Dubai)
A6: Arrival window 1 | B6: 08:00 - 12:00
A7: Arrival window 2 | B7: 12:00 - 16:00
A8: Arrival window 3 | B8: 16:00 - 21:00
A9: Arrival promise | B9: Team arrives within the window; up to 1 hour delay possible due to traffic. Service hours start when the team arrives.
A10: Same-day booking | B10: Allowed until 18:00 for the 16:00-21:00 window, only if a team is free. After 18:00 the first bookable slot is tomorrow 08:00-12:00.
A11: Lead time (BookingKoala 'minimum notice') | B11: 2 hours
A12: Booking horizon | B12: 30 days ahead
A13: Teams / providers | B13: Enter the number of cleaners available per day so the calendar blocks capacity correctly (fill in).
A14: Buffer between jobs | B14: 60 minutes travel (fill in if different)
... A16: Discount codes / tips | B16: OFF

Sheet 5 Policies & texts
A1: Texts to paste into BookingKoala
A3: Where | B3: Text (English) | C3: Text (Arabic)
A4: Service description: Kitchen deep cleaning | B4: Cooker, hob, hood and oven steam cleaned inside and out. Fridge inside and out, every cabinet inside, outside and on top. Walls, tiles, grout, sink and floor. Food-safe: you can cook right after. Our trained all-female team brings all machines, tools and materials. Also choose this package for bathrooms only, kitchen + bathrooms, one room, balcony, inside windows or a full home refresh, and tell our team what to focus on when they confirm. | C4: البوتاجاز والشفاط والفرن بالبخار من الداخل والخارج. الثلاجة من الداخل والخارج، وكل الخزائن من الداخل والخارج ومن فوق. الجدران والسيراميك والفواصل والحوض والأرضية. آمن على الأكل: تقدر تطبخ بعدها مباشرة. فريقنا النسائي المدرّب يجيب كل الماكينات والأدوات والمواد.
A5: Service description: Full house deep cleaning | B5: Kitchen and bathrooms deep cleaned with high-temperature steam. Bedrooms, living areas, floors, doors, windows, AC vents and balcony deep cleaned by hand. Furniture moved and cleaned behind. Our trained all-female team brings everything. | C5: المطبخ والحمامات بالبخار بدرجة حرارة عالية. غرف النوم والصالة والأرضيات والأبواب والشبابيك وفتحات التكييف والبلكونة تنظيف عميق يدوي. نحرّك الأثاث وننظف وراه. فريقنا النسائي المدرّب يجيب كل شي.
A6: Price note under the form | B6: The price shown is the total: team, hours, transport, steam machine, tools and materials included. No call-out fee. Pay on completion by cash, card payment link or bank transfer. | C6: السعر المعروض هو الإجمالي: الفريق والساعات والمواصلات وماكينة البخار والأدوات والمواد. بدون رسوم زيارة. الدفع بعد الانتهاء نقداً أو برابط بطاقة أو تحويل بنكي.
A7: Cancellation policy | B7: Reschedule: one free reschedule if requested more than 24 hours before, subject to availability. Less than 24 hours: only against a deposit toward the new booking; a second reschedule counts as a cancellation. Cancellation: more than 12 hours before - no charge. 12 to 8 hours before - 30%. Less than 8 hours and before dispatch - 50%. After dispatch, on arrival, or no access - 100%. If we cancel - no charge and we offer the earliest slot. | C7: إعادة الجدولة: مرة واحدة مجاناً إذا طُلبت قبل أكثر من 24 ساعة وحسب التوفر. أقل من 24 ساعة: مقابل عربون يُحتسب من الحجز الجديد؛ إعادة الجدولة الثانية تُعتبر إلغاء. الإلغاء: قبل أكثر من 12 ساعة بدون رسوم. من 12 إلى 8 ساعات 30%. أقل من 8 ساعات وقبل انطلاق الفريق 50%. بعد الانطلاق أو عند الوصول أو عدم التمكن من الدخول 100%. إذا ألغينا نحن: بدون رسوم ونقدم أقرب موعد.
A8: Booking confirmation message | B8: Thank you for booking with Just Now 😊 Our team will confirm your booking with you on WhatsApp shortly. Please make sure running water and electricity are available and someone can open the door. You can add one more hour on the day if needed; tell the team before the last booked hour starts. | C8: شكراً لحجزك مع جست ناو 😊 فريقنا بيأكد حجزك معك على الواتساب قريباً. الرجاء التأكد من توفر الماء والكهرباء ووجود شخص لفتح الباب. تقدر تضيف ساعة إضافية في نفس اليوم إذا احتجت؛ خبر الفريق قبل بداية آخر ساعة محجوزة.
A9: Quality guarantee | B9: Report any issue on site or within 24 hours and we redo that part free of charge. We do not repair pre-existing damage. | C9: بلّغنا عن أي ملاحظة في الموقع أو خلال 24 ساعة ونعيد تنظيف ذلك الجزء مجاناً. لا نصلح الأضرار الموجودة مسبقاً.
A10: Not bookable online (show as a note) | B10: Sofa, mattress, carpet and curtains, offices and shops, Abu Dhabi and Al Ain: message us on WhatsApp +971 50 767 7282 with photos or a video for an exact price. | C10: الكنب والمراتب والسجاد والستائر، المكاتب والمحلات، أبوظبي والعين: راسلنا على واتساب +971 50 767 7282 مع صور أو فيديو لسعر دقيق.

Sheet 6 Price check
A1: Price check (type an area and pick a size; the zone and prices appear)
A2: Use this to verify BookingKoala after setup: the price it shows must equal column C here. Yellow cells are inputs.
A4: Area (type exactly as in sheet 3) | B4: Al Majaz
A5: Service / size (Kitchen only / partial / refresh, Studio, 1 BHK, 2 BHK, 3 BHK, Villa 4 BR, Villa 5+ BR) | B5: Kitchen only / partial / refresh
A7: Zone | B7: =IFERROR(INDEX('3 Zones & Areas'!$F$5:$F$343,MATCH($B$4,'3 Zones & Areas'!$C$5:$C$343,0)),"Area not listed - price on request") -> Zone A
A8: Lookup key | B8: =IF(LEFT($B$5,7)="Kitchen","Kitchen only / partial / refresh",$B$5)&"|"&$B$7 -> Kitchen only / partial / refresh|Zone A
A10: Package | B10: Cleaners x hours | C10: Price AED
A11: Package 1 (shown first / minimum) | B11: =IFERROR(INDEX('2 Packages'!$F$5:$F$109,MATCH($B$8&"|1",'2 Packages'!$L$5:$L$109,0)),"-") -> 2 cleaners x 3 hours | C11: =IFERROR(INDEX('2 Packages'!$I$5:$I$109,MATCH($B$8&"|1",'2 Packages'!$L$5:$L$109,0)),"-") -> 249
A12: Package 2 | B12: =IFERROR(INDEX('2 Packages'!$F$5:$F$109,MATCH($B$8&"|2",'2 Packages'!$L$5:$L$109,0)),"-") -> 2 cleaners x 4 hours | C12: =IFERROR(INDEX('2 Packages'!$I$5:$I$109,MATCH($B$8&"|2",'2 Packages'!$L$5:$L$109,0)),"-") -> 329
A13: Package 3 | B13: =IFERROR(INDEX('2 Packages'!$F$5:$F$109,MATCH($B$8&"|3",'2 Packages'!$L$5:$L$109,0)),"-") -> 2 cleaners x 5 hours | C13: =IFERROR(INDEX('2 Packages'!$I$5:$I$109,MATCH($B$8&"|3",'2 Packages'!$L$5:$L$109,0)),"-") -> 419
